2021-11-23 21:10:12,564 - ERROR - default_exception_handler: 1707 - Task exception was never retrieved
future: <Task finished name='Task-36' coro=<Dispatcher._process_polling_updates() done, defined at C:\Users\Максим\AppData\Roaming\Python\Python38\site-packages\aiogram\dispatcher\dispatcher.py:406> exception=KeyError(1073956394)>
Traceback (most recent call last):
  File "C:\Users\Максим\AppData\Roaming\Python\Python38\site-packages\aiogram\dispatcher\dispatcher.py", line 414, in _process_polling_updates
    for responses in itertools.chain.from_iterable(await self.process_updates(updates, fast)):
  File "C:\Users\Максим\AppData\Roaming\Python\Python38\site-packages\aiogram\dispatcher\dispatcher.py", line 236, in process_updates
    return await asyncio.gather(*tasks)
  File "C:\Users\Максим\AppData\Roaming\Python\Python38\site-packages\aiogram\dispatcher\handler.py", line 116, in notify
    response = await handler_obj.handler(*args, **partial_data)
  File "C:\Users\Максим\AppData\Roaming\Python\Python38\site-packages\aiogram\dispatcher\dispatcher.py", line 257, in process_update
    return await self.message_handlers.notify(update.message)
  File "C:\Users\Максим\AppData\Roaming\Python\Python38\site-packages\aiogram\dispatcher\handler.py", line 116, in notify
    response = await handler_obj.handler(*args, **partial_data)
  File "c:\Users\Максим\Desktop\telega но другая\telegram_bot - копия.py", line 33, in first_test_state_case_met
    smth = dic_id[msg_us_id]
KeyError: 1073956394
2021-11-23 21:14:31,325 - ERROR - default_exception_handler: 1707 - Task exception was never retrieved
future: <Task finished name='Task-83' coro=<Dispatcher._process_polling_updates() done, defined at C:\Users\Максим\AppData\Roaming\Python\Python38\site-packages\aiogram\dispatcher\dispatcher.py:406> exception=KeyError(1073956394)>
Traceback (most recent call last):
  File "C:\Users\Максим\AppData\Roaming\Python\Python38\site-packages\aiogram\dispatcher\dispatcher.py", line 414, in _process_polling_updates
    for responses in itertools.chain.from_iterable(await self.process_updates(updates, fast)):
  File "C:\Users\Максим\AppData\Roaming\Python\Python38\site-packages\aiogram\dispatcher\dispatcher.py", line 236, in process_updates
    return await asyncio.gather(*tasks)
  File "C:\Users\Максим\AppData\Roaming\Python\Python38\site-packages\aiogram\dispatcher\handler.py", line 116, in notify
    response = await handler_obj.handler(*args, **partial_data)
  File "C:\Users\Максим\AppData\Roaming\Python\Python38\site-packages\aiogram\dispatcher\dispatcher.py", line 257, in process_update
    return await self.message_handlers.notify(update.message)
  File "C:\Users\Максим\AppData\Roaming\Python\Python38\site-packages\aiogram\dispatcher\handler.py", line 116, in notify
    response = await handler_obj.handler(*args, **partial_data)
  File "c:\Users\Максим\Desktop\telega но другая\telegram_bot - копия.py", line 33, in first_test_state_case_met
    smth = dic_id[msg_us_id]
KeyError: 1073956394
2021-11-23 23:52:55,473 - ERROR - default_exception_handler: 1707 - Task exception was never retrieved
future: <Task finished name='Task-44' coro=<Dispatcher._process_polling_updates() done, defined at C:\Users\Максим\AppData\Roaming\Python\Python38\site-packages\aiogram\dispatcher\dispatcher.py:406> exception=KeyError(1073956394)>
Traceback (most recent call last):
  File "C:\Users\Максим\AppData\Roaming\Python\Python38\site-packages\aiogram\dispatcher\dispatcher.py", line 414, in _process_polling_updates
    for responses in itertools.chain.from_iterable(await self.process_updates(updates, fast)):
  File "C:\Users\Максим\AppData\Roaming\Python\Python38\site-packages\aiogram\dispatcher\dispatcher.py", line 236, in process_updates
    return await asyncio.gather(*tasks)
  File "C:\Users\Максим\AppData\Roaming\Python\Python38\site-packages\aiogram\dispatcher\handler.py", line 116, in notify
    response = await handler_obj.handler(*args, **partial_data)
  File "C:\Users\Максим\AppData\Roaming\Python\Python38\site-packages\aiogram\dispatcher\dispatcher.py", line 257, in process_update
    return await self.message_handlers.notify(update.message)
  File "C:\Users\Максим\AppData\Roaming\Python\Python38\site-packages\aiogram\dispatcher\handler.py", line 116, in notify
    response = await handler_obj.handler(*args, **partial_data)
  File "c:\Users\Максим\Desktop\telegram bot\telegram_bot - копия.py", line 32, in first_test_state_case_met
    smth = dic_id[msg_us_id]
KeyError: 1073956394
2021-11-23 23:52:56,814 - ERROR - default_exception_handler: 1707 - Task exception was never retrieved
future: <Task finished name='Task-48' coro=<Dispatcher._process_polling_updates() done, defined at C:\Users\Максим\AppData\Roaming\Python\Python38\site-packages\aiogram\dispatcher\dispatcher.py:406> exception=KeyError(1073956394)>
Traceback (most recent call last):
  File "C:\Users\Максим\AppData\Roaming\Python\Python38\site-packages\aiogram\dispatcher\dispatcher.py", line 414, in _process_polling_updates
    for responses in itertools.chain.from_iterable(await self.process_updates(updates, fast)):
  File "C:\Users\Максим\AppData\Roaming\Python\Python38\site-packages\aiogram\dispatcher\dispatcher.py", line 236, in process_updates
    return await asyncio.gather(*tasks)
  File "C:\Users\Максим\AppData\Roaming\Python\Python38\site-packages\aiogram\dispatcher\handler.py", line 116, in notify
    response = await handler_obj.handler(*args, **partial_data)
  File "C:\Users\Максим\AppData\Roaming\Python\Python38\site-packages\aiogram\dispatcher\dispatcher.py", line 257, in process_update
    return await self.message_handlers.notify(update.message)
  File "C:\Users\Максим\AppData\Roaming\Python\Python38\site-packages\aiogram\dispatcher\handler.py", line 116, in notify
    response = await handler_obj.handler(*args, **partial_data)
  File "c:\Users\Максим\Desktop\telegram bot\telegram_bot - копия.py", line 32, in first_test_state_case_met
    smth = dic_id[msg_us_id]
KeyError: 1073956394
2021-11-23 23:52:58,308 - ERROR - default_exception_handler: 1707 - Task exception was never retrieved
future: <Task finished name='Task-52' coro=<Dispatcher._process_polling_updates() done, defined at C:\Users\Максим\AppData\Roaming\Python\Python38\site-packages\aiogram\dispatcher\dispatcher.py:406> exception=KeyError(1073956394)>
Traceback (most recent call last):
  File "C:\Users\Максим\AppData\Roaming\Python\Python38\site-packages\aiogram\dispatcher\dispatcher.py", line 414, in _process_polling_updates
    for responses in itertools.chain.from_iterable(await self.process_updates(updates, fast)):
  File "C:\Users\Максим\AppData\Roaming\Python\Python38\site-packages\aiogram\dispatcher\dispatcher.py", line 236, in process_updates
    return await asyncio.gather(*tasks)
  File "C:\Users\Максим\AppData\Roaming\Python\Python38\site-packages\aiogram\dispatcher\handler.py", line 116, in notify
    response = await handler_obj.handler(*args, **partial_data)
  File "C:\Users\Максим\AppData\Roaming\Python\Python38\site-packages\aiogram\dispatcher\dispatcher.py", line 257, in process_update
    return await self.message_handlers.notify(update.message)
  File "C:\Users\Максим\AppData\Roaming\Python\Python38\site-packages\aiogram\dispatcher\handler.py", line 116, in notify
    response = await handler_obj.handler(*args, **partial_data)
  File "c:\Users\Максим\Desktop\telegram bot\telegram_bot - копия.py", line 32, in first_test_state_case_met
    smth = dic_id[msg_us_id]
KeyError: 1073956394
2021-11-23 23:57:05,399 - ERROR - default_exception_handler: 1707 - Task exception was never retrieved
future: <Task finished name='Task-44' coro=<Dispatcher._process_polling_updates() done, defined at C:\Users\Максим\AppData\Roaming\Python\Python38\site-packages\aiogram\dispatcher\dispatcher.py:406> exception=KeyError(1073956394)>
Traceback (most recent call last):
  File "C:\Users\Максим\AppData\Roaming\Python\Python38\site-packages\aiogram\dispatcher\dispatcher.py", line 414, in _process_polling_updates
    for responses in itertools.chain.from_iterable(await self.process_updates(updates, fast)):
  File "C:\Users\Максим\AppData\Roaming\Python\Python38\site-packages\aiogram\dispatcher\dispatcher.py", line 236, in process_updates
    return await asyncio.gather(*tasks)
  File "C:\Users\Максим\AppData\Roaming\Python\Python38\site-packages\aiogram\dispatcher\handler.py", line 116, in notify
    response = await handler_obj.handler(*args, **partial_data)
  File "C:\Users\Максим\AppData\Roaming\Python\Python38\site-packages\aiogram\dispatcher\dispatcher.py", line 257, in process_update
    return await self.message_handlers.notify(update.message)
  File "C:\Users\Максим\AppData\Roaming\Python\Python38\site-packages\aiogram\dispatcher\handler.py", line 116, in notify
    response = await handler_obj.handler(*args, **partial_data)
  File "c:\Users\Максим\Desktop\telegram bot\telegram_bot - копия.py", line 32, in first_test_state_case_met
    smth = dic_id[msg_us_id]
KeyError: 1073956394
2021-11-23 23:57:06,685 - ERROR - default_exception_handler: 1707 - Task exception was never retrieved
future: <Task finished name='Task-48' coro=<Dispatcher._process_polling_updates() done, defined at C:\Users\Максим\AppData\Roaming\Python\Python38\site-packages\aiogram\dispatcher\dispatcher.py:406> exception=KeyError(1073956394)>
Traceback (most recent call last):
  File "C:\Users\Максим\AppData\Roaming\Python\Python38\site-packages\aiogram\dispatcher\dispatcher.py", line 414, in _process_polling_updates
    for responses in itertools.chain.from_iterable(await self.process_updates(updates, fast)):
  File "C:\Users\Максим\AppData\Roaming\Python\Python38\site-packages\aiogram\dispatcher\dispatcher.py", line 236, in process_updates
    return await asyncio.gather(*tasks)
  File "C:\Users\Максим\AppData\Roaming\Python\Python38\site-packages\aiogram\dispatcher\handler.py", line 116, in notify
    response = await handler_obj.handler(*args, **partial_data)
  File "C:\Users\Максим\AppData\Roaming\Python\Python38\site-packages\aiogram\dispatcher\dispatcher.py", line 257, in process_update
    return await self.message_handlers.notify(update.message)
  File "C:\Users\Максим\AppData\Roaming\Python\Python38\site-packages\aiogram\dispatcher\handler.py", line 116, in notify
    response = await handler_obj.handler(*args, **partial_data)
  File "c:\Users\Максим\Desktop\telegram bot\telegram_bot - копия.py", line 32, in first_test_state_case_met
    smth = dic_id[msg_us_id]
KeyError: 1073956394
2021-11-23 23:57:07,636 - ERROR - default_exception_handler: 1707 - Task exception was never retrieved
future: <Task finished name='Task-52' coro=<Dispatcher._process_polling_updates() done, defined at C:\Users\Максим\AppData\Roaming\Python\Python38\site-packages\aiogram\dispatcher\dispatcher.py:406> exception=KeyError(1073956394)>
Traceback (most recent call last):
  File "C:\Users\Максим\AppData\Roaming\Python\Python38\site-packages\aiogram\dispatcher\dispatcher.py", line 414, in _process_polling_updates
    for responses in itertools.chain.from_iterable(await self.process_updates(updates, fast)):
  File "C:\Users\Максим\AppData\Roaming\Python\Python38\site-packages\aiogram\dispatcher\dispatcher.py", line 236, in process_updates
    return await asyncio.gather(*tasks)
  File "C:\Users\Максим\AppData\Roaming\Python\Python38\site-packages\aiogram\dispatcher\handler.py", line 116, in notify
    response = await handler_obj.handler(*args, **partial_data)
  File "C:\Users\Максим\AppData\Roaming\Python\Python38\site-packages\aiogram\dispatcher\dispatcher.py", line 257, in process_update
    return await self.message_handlers.notify(update.message)
  File "C:\Users\Максим\AppData\Roaming\Python\Python38\site-packages\aiogram\dispatcher\handler.py", line 116, in notify
    response = await handler_obj.handler(*args, **partial_data)
  File "c:\Users\Максим\Desktop\telegram bot\telegram_bot - копия.py", line 32, in first_test_state_case_met
    smth = dic_id[msg_us_id]
KeyError: 1073956394
2021-11-23 23:57:08,366 - ERROR - default_exception_handler: 1707 - Task exception was never retrieved
future: <Task finished name='Task-56' coro=<Dispatcher._process_polling_updates() done, defined at C:\Users\Максим\AppData\Roaming\Python\Python38\site-packages\aiogram\dispatcher\dispatcher.py:406> exception=KeyError(1073956394)>
Traceback (most recent call last):
  File "C:\Users\Максим\AppData\Roaming\Python\Python38\site-packages\aiogram\dispatcher\dispatcher.py", line 414, in _process_polling_updates
    for responses in itertools.chain.from_iterable(await self.process_updates(updates, fast)):
  File "C:\Users\Максим\AppData\Roaming\Python\Python38\site-packages\aiogram\dispatcher\dispatcher.py", line 236, in process_updates
    return await asyncio.gather(*tasks)
  File "C:\Users\Максим\AppData\Roaming\Python\Python38\site-packages\aiogram\dispatcher\handler.py", line 116, in notify
    response = await handler_obj.handler(*args, **partial_data)
  File "C:\Users\Максим\AppData\Roaming\Python\Python38\site-packages\aiogram\dispatcher\dispatcher.py", line 257, in process_update
    return await self.message_handlers.notify(update.message)
  File "C:\Users\Максим\AppData\Roaming\Python\Python38\site-packages\aiogram\dispatcher\handler.py", line 116, in notify
    response = await handler_obj.handler(*args, **partial_data)
  File "c:\Users\Максим\Desktop\telegram bot\telegram_bot - копия.py", line 32, in first_test_state_case_met
    smth = dic_id[msg_us_id]
KeyError: 1073956394
2021-11-23 23:57:10,244 - ERROR - default_exception_handler: 1707 - Task exception was never retrieved
future: <Task finished name='Task-60' coro=<Dispatcher._process_polling_updates() done, defined at C:\Users\Максим\AppData\Roaming\Python\Python38\site-packages\aiogram\dispatcher\dispatcher.py:406> exception=KeyError(1073956394)>
Traceback (most recent call last):
  File "C:\Users\Максим\AppData\Roaming\Python\Python38\site-packages\aiogram\dispatcher\dispatcher.py", line 414, in _process_polling_updates
    for responses in itertools.chain.from_iterable(await self.process_updates(updates, fast)):
  File "C:\Users\Максим\AppData\Roaming\Python\Python38\site-packages\aiogram\dispatcher\dispatcher.py", line 236, in process_updates
    return await asyncio.gather(*tasks)
  File "C:\Users\Максим\AppData\Roaming\Python\Python38\site-packages\aiogram\dispatcher\handler.py", line 116, in notify
    response = await handler_obj.handler(*args, **partial_data)
  File "C:\Users\Максим\AppData\Roaming\Python\Python38\site-packages\aiogram\dispatcher\dispatcher.py", line 257, in process_update
    return await self.message_handlers.notify(update.message)
  File "C:\Users\Максим\AppData\Roaming\Python\Python38\site-packages\aiogram\dispatcher\handler.py", line 116, in notify
    response = await handler_obj.handler(*args, **partial_data)
  File "c:\Users\Максим\Desktop\telegram bot\telegram_bot - копия.py", line 32, in first_test_state_case_met
    smth = dic_id[msg_us_id]
KeyError: 1073956394
2021-11-23 23:57:34,178 - ERROR - default_exception_handler: 1707 - Task exception was never retrieved
future: <Task finished name='Task-65' coro=<Dispatcher._process_polling_updates() done, defined at C:\Users\Максим\AppData\Roaming\Python\Python38\site-packages\aiogram\dispatcher\dispatcher.py:406> exception=KeyError(1073956394)>
Traceback (most recent call last):
  File "C:\Users\Максим\AppData\Roaming\Python\Python38\site-packages\aiogram\dispatcher\dispatcher.py", line 414, in _process_polling_updates
    for responses in itertools.chain.from_iterable(await self.process_updates(updates, fast)):
  File "C:\Users\Максим\AppData\Roaming\Python\Python38\site-packages\aiogram\dispatcher\dispatcher.py", line 236, in process_updates
    return await asyncio.gather(*tasks)
  File "C:\Users\Максим\AppData\Roaming\Python\Python38\site-packages\aiogram\dispatcher\handler.py", line 116, in notify
    response = await handler_obj.handler(*args, **partial_data)
  File "C:\Users\Максим\AppData\Roaming\Python\Python38\site-packages\aiogram\dispatcher\dispatcher.py", line 257, in process_update
    return await self.message_handlers.notify(update.message)
  File "C:\Users\Максим\AppData\Roaming\Python\Python38\site-packages\aiogram\dispatcher\handler.py", line 116, in notify
    response = await handler_obj.handler(*args, **partial_data)
  File "c:\Users\Максим\Desktop\telegram bot\telegram_bot - копия.py", line 32, in first_test_state_case_met
    smth = dic_id[msg_us_id]
KeyError: 1073956394
2021-11-23 23:58:12,235 - ERROR - default_exception_handler: 1707 - Task exception was never retrieved
future: <Task finished name='Task-71' coro=<Dispatcher._process_polling_updates() done, defined at C:\Users\Максим\AppData\Roaming\Python\Python38\site-packages\aiogram\dispatcher\dispatcher.py:406> exception=KeyError(1073956394)>
Traceback (most recent call last):
  File "C:\Users\Максим\AppData\Roaming\Python\Python38\site-packages\aiogram\dispatcher\dispatcher.py", line 414, in _process_polling_updates
    for responses in itertools.chain.from_iterable(await self.process_updates(updates, fast)):
  File "C:\Users\Максим\AppData\Roaming\Python\Python38\site-packages\aiogram\dispatcher\dispatcher.py", line 236, in process_updates
    return await asyncio.gather(*tasks)
  File "C:\Users\Максим\AppData\Roaming\Python\Python38\site-packages\aiogram\dispatcher\handler.py", line 116, in notify
    response = await handler_obj.handler(*args, **partial_data)
  File "C:\Users\Максим\AppData\Roaming\Python\Python38\site-packages\aiogram\dispatcher\dispatcher.py", line 257, in process_update
    return await self.message_handlers.notify(update.message)
  File "C:\Users\Максим\AppData\Roaming\Python\Python38\site-packages\aiogram\dispatcher\handler.py", line 116, in notify
    response = await handler_obj.handler(*args, **partial_data)
  File "c:\Users\Максим\Desktop\telegram bot\telegram_bot - копия.py", line 32, in first_test_state_case_met
    smth = dic_id[msg_us_id]
KeyError: 1073956394
2021-11-23 23:58:13,357 - ERROR - default_exception_handler: 1707 - Task exception was never retrieved
future: <Task finished name='Task-75' coro=<Dispatcher._process_polling_updates() done, defined at C:\Users\Максим\AppData\Roaming\Python\Python38\site-packages\aiogram\dispatcher\dispatcher.py:406> exception=KeyError(1073956394)>
Traceback (most recent call last):
  File "C:\Users\Максим\AppData\Roaming\Python\Python38\site-packages\aiogram\dispatcher\dispatcher.py", line 414, in _process_polling_updates
    for responses in itertools.chain.from_iterable(await self.process_updates(updates, fast)):
  File "C:\Users\Максим\AppData\Roaming\Python\Python38\site-packages\aiogram\dispatcher\dispatcher.py", line 236, in process_updates
    return await asyncio.gather(*tasks)
  File "C:\Users\Максим\AppData\Roaming\Python\Python38\site-packages\aiogram\dispatcher\handler.py", line 116, in notify
    response = await handler_obj.handler(*args, **partial_data)
  File "C:\Users\Максим\AppData\Roaming\Python\Python38\site-packages\aiogram\dispatcher\dispatcher.py", line 257, in process_update
    return await self.message_handlers.notify(update.message)
  File "C:\Users\Максим\AppData\Roaming\Python\Python38\site-packages\aiogram\dispatcher\handler.py", line 116, in notify
    response = await handler_obj.handler(*args, **partial_data)
  File "c:\Users\Максим\Desktop\telegram bot\telegram_bot - копия.py", line 32, in first_test_state_case_met
    smth = dic_id[msg_us_id]
KeyError: 1073956394
2021-11-23 23:58:14,030 - ERROR - default_exception_handler: 1707 - Task exception was never retrieved
future: <Task finished name='Task-80' coro=<Dispatcher._process_polling_updates() done, defined at C:\Users\Максим\AppData\Roaming\Python\Python38\site-packages\aiogram\dispatcher\dispatcher.py:406> exception=KeyError(1073956394)>
Traceback (most recent call last):
  File "C:\Users\Максим\AppData\Roaming\Python\Python38\site-packages\aiogram\dispatcher\dispatcher.py", line 414, in _process_polling_updates
    for responses in itertools.chain.from_iterable(await self.process_updates(updates, fast)):
  File "C:\Users\Максим\AppData\Roaming\Python\Python38\site-packages\aiogram\dispatcher\dispatcher.py", line 236, in process_updates
    return await asyncio.gather(*tasks)
  File "C:\Users\Максим\AppData\Roaming\Python\Python38\site-packages\aiogram\dispatcher\handler.py", line 116, in notify
    response = await handler_obj.handler(*args, **partial_data)
  File "C:\Users\Максим\AppData\Roaming\Python\Python38\site-packages\aiogram\dispatcher\dispatcher.py", line 257, in process_update
    return await self.message_handlers.notify(update.message)
  File "C:\Users\Максим\AppData\Roaming\Python\Python38\site-packages\aiogram\dispatcher\handler.py", line 116, in notify
    response = await handler_obj.handler(*args, **partial_data)
  File "c:\Users\Максим\Desktop\telegram bot\telegram_bot - копия.py", line 32, in first_test_state_case_met
    smth = dic_id[msg_us_id]
KeyError: 1073956394
2021-11-23 23:58:14,468 - ERROR - default_exception_handler: 1707 - Task exception was never retrieved
future: <Task finished name='Task-84' coro=<Dispatcher._process_polling_updates() done, defined at C:\Users\Максим\AppData\Roaming\Python\Python38\site-packages\aiogram\dispatcher\dispatcher.py:406> exception=KeyError(1073956394)>
Traceback (most recent call last):
  File "C:\Users\Максим\AppData\Roaming\Python\Python38\site-packages\aiogram\dispatcher\dispatcher.py", line 414, in _process_polling_updates
    for responses in itertools.chain.from_iterable(await self.process_updates(updates, fast)):
  File "C:\Users\Максим\AppData\Roaming\Python\Python38\site-packages\aiogram\dispatcher\dispatcher.py", line 236, in process_updates
    return await asyncio.gather(*tasks)
  File "C:\Users\Максим\AppData\Roaming\Python\Python38\site-packages\aiogram\dispatcher\handler.py", line 116, in notify
    response = await handler_obj.handler(*args, **partial_data)
  File "C:\Users\Максим\AppData\Roaming\Python\Python38\site-packages\aiogram\dispatcher\dispatcher.py", line 257, in process_update
    return await self.message_handlers.notify(update.message)
  File "C:\Users\Максим\AppData\Roaming\Python\Python38\site-packages\aiogram\dispatcher\handler.py", line 116, in notify
    response = await handler_obj.handler(*args, **partial_data)
  File "c:\Users\Максим\Desktop\telegram bot\telegram_bot - копия.py", line 32, in first_test_state_case_met
    smth = dic_id[msg_us_id]
KeyError: 1073956394
2021-11-24 00:06:07,321 - ERROR - default_exception_handler: 1707 - Task exception was never retrieved
future: <Task finished name='Task-7' coro=<Dispatcher._process_polling_updates() done, defined at C:\Users\Максим\AppData\Roaming\Python\Python38\site-packages\aiogram\dispatcher\dispatcher.py:406> exception=AttributeError("'Dispatcher' object has no attribute 'get_state'")>
Traceback (most recent call last):
  File "C:\Users\Максим\AppData\Roaming\Python\Python38\site-packages\aiogram\dispatcher\dispatcher.py", line 414, in _process_polling_updates
    for responses in itertools.chain.from_iterable(await self.process_updates(updates, fast)):
  File "C:\Users\Максим\AppData\Roaming\Python\Python38\site-packages\aiogram\dispatcher\dispatcher.py", line 236, in process_updates
    return await asyncio.gather(*tasks)
  File "C:\Users\Максим\AppData\Roaming\Python\Python38\site-packages\aiogram\dispatcher\handler.py", line 116, in notify
    response = await handler_obj.handler(*args, **partial_data)
  File "C:\Users\Максим\AppData\Roaming\Python\Python38\site-packages\aiogram\dispatcher\dispatcher.py", line 257, in process_update
    return await self.message_handlers.notify(update.message)
  File "C:\Users\Максим\AppData\Roaming\Python\Python38\site-packages\aiogram\dispatcher\handler.py", line 116, in notify
    response = await handler_obj.handler(*args, **partial_data)
  File "c:\Users\Максим\Desktop\telegram bot\telegram_bot - копия.py", line 92, in process_start_command
    state = await dp.get_state()
AttributeError: 'Dispatcher' object has no attribute 'get_state'
2021-11-24 00:06:25,776 - ERROR - default_exception_handler: 1707 - Task exception was never retrieved
future: <Task finished name='Task-10' coro=<Dispatcher._process_polling_updates() done, defined at C:\Users\Максим\AppData\Roaming\Python\Python38\site-packages\aiogram\dispatcher\dispatcher.py:406> exception=AttributeError("'Dispatcher' object has no attribute 'get_state'")>
Traceback (most recent call last):
  File "C:\Users\Максим\AppData\Roaming\Python\Python38\site-packages\aiogram\dispatcher\dispatcher.py", line 414, in _process_polling_updates
    for responses in itertools.chain.from_iterable(await self.process_updates(updates, fast)):
  File "C:\Users\Максим\AppData\Roaming\Python\Python38\site-packages\aiogram\dispatcher\dispatcher.py", line 236, in process_updates
    return await asyncio.gather(*tasks)
  File "C:\Users\Максим\AppData\Roaming\Python\Python38\site-packages\aiogram\dispatcher\handler.py", line 116, in notify
    response = await handler_obj.handler(*args, **partial_data)
  File "C:\Users\Максим\AppData\Roaming\Python\Python38\site-packages\aiogram\dispatcher\dispatcher.py", line 257, in process_update
    return await self.message_handlers.notify(update.message)
  File "C:\Users\Максим\AppData\Roaming\Python\Python38\site-packages\aiogram\dispatcher\handler.py", line 116, in notify
    response = await handler_obj.handler(*args, **partial_data)
  File "c:\Users\Максим\Desktop\telegram bot\telegram_bot - копия.py", line 92, in process_start_command
    state = await dp.get_state()
AttributeError: 'Dispatcher' object has no attribute 'get_state'
2021-11-24 00:06:26,714 - ERROR - default_exception_handler: 1707 - Task exception was never retrieved
future: <Task finished name='Task-13' coro=<Dispatcher._process_polling_updates() done, defined at C:\Users\Максим\AppData\Roaming\Python\Python38\site-packages\aiogram\dispatcher\dispatcher.py:406> exception=AttributeError("'Dispatcher' object has no attribute 'get_state'")>
Traceback (most recent call last):
  File "C:\Users\Максим\AppData\Roaming\Python\Python38\site-packages\aiogram\dispatcher\dispatcher.py", line 414, in _process_polling_updates
    for responses in itertools.chain.from_iterable(await self.process_updates(updates, fast)):
  File "C:\Users\Максим\AppData\Roaming\Python\Python38\site-packages\aiogram\dispatcher\dispatcher.py", line 236, in process_updates
    return await asyncio.gather(*tasks)
  File "C:\Users\Максим\AppData\Roaming\Python\Python38\site-packages\aiogram\dispatcher\handler.py", line 116, in notify
    response = await handler_obj.handler(*args, **partial_data)
  File "C:\Users\Максим\AppData\Roaming\Python\Python38\site-packages\aiogram\dispatcher\dispatcher.py", line 257, in process_update
    return await self.message_handlers.notify(update.message)
  File "C:\Users\Максим\AppData\Roaming\Python\Python38\site-packages\aiogram\dispatcher\handler.py", line 116, in notify
    response = await handler_obj.handler(*args, **partial_data)
  File "c:\Users\Максим\Desktop\telegram bot\telegram_bot - копия.py", line 92, in process_start_command
    state = await dp.get_state()
AttributeError: 'Dispatcher' object has no attribute 'get_state'
2021-11-24 00:06:28,428 - ERROR - default_exception_handler: 1707 - Task exception was never retrieved
future: <Task finished name='Task-16' coro=<Dispatcher._process_polling_updates() done, defined at C:\Users\Максим\AppData\Roaming\Python\Python38\site-packages\aiogram\dispatcher\dispatcher.py:406> exception=AttributeError("'Dispatcher' object has no attribute 'get_state'")>
Traceback (most recent call last):
  File "C:\Users\Максим\AppData\Roaming\Python\Python38\site-packages\aiogram\dispatcher\dispatcher.py", line 414, in _process_polling_updates
    for responses in itertools.chain.from_iterable(await self.process_updates(updates, fast)):
  File "C:\Users\Максим\AppData\Roaming\Python\Python38\site-packages\aiogram\dispatcher\dispatcher.py", line 236, in process_updates
    return await asyncio.gather(*tasks)
  File "C:\Users\Максим\AppData\Roaming\Python\Python38\site-packages\aiogram\dispatcher\handler.py", line 116, in notify
    response = await handler_obj.handler(*args, **partial_data)
  File "C:\Users\Максим\AppData\Roaming\Python\Python38\site-packages\aiogram\dispatcher\dispatcher.py", line 257, in process_update
    return await self.message_handlers.notify(update.message)
  File "C:\Users\Максим\AppData\Roaming\Python\Python38\site-packages\aiogram\dispatcher\handler.py", line 116, in notify
    response = await handler_obj.handler(*args, **partial_data)
  File "c:\Users\Максим\Desktop\telegram bot\telegram_bot - копия.py", line 92, in process_start_command
    state = await dp.get_state()
AttributeError: 'Dispatcher' object has no attribute 'get_state'
2021-11-24 00:06:28,925 - ERROR - default_exception_handler: 1707 - Task exception was never retrieved
future: <Task finished name='Task-19' coro=<Dispatcher._process_polling_updates() done, defined at C:\Users\Максим\AppData\Roaming\Python\Python38\site-packages\aiogram\dispatcher\dispatcher.py:406> exception=AttributeError("'Dispatcher' object has no attribute 'get_state'")>
Traceback (most recent call last):
  File "C:\Users\Максим\AppData\Roaming\Python\Python38\site-packages\aiogram\dispatcher\dispatcher.py", line 414, in _process_polling_updates
    for responses in itertools.chain.from_iterable(await self.process_updates(updates, fast)):
  File "C:\Users\Максим\AppData\Roaming\Python\Python38\site-packages\aiogram\dispatcher\dispatcher.py", line 236, in process_updates
    return await asyncio.gather(*tasks)
  File "C:\Users\Максим\AppData\Roaming\Python\Python38\site-packages\aiogram\dispatcher\handler.py", line 116, in notify
    response = await handler_obj.handler(*args, **partial_data)
  File "C:\Users\Максим\AppData\Roaming\Python\Python38\site-packages\aiogram\dispatcher\dispatcher.py", line 257, in process_update
    return await self.message_handlers.notify(update.message)
  File "C:\Users\Максим\AppData\Roaming\Python\Python38\site-packages\aiogram\dispatcher\handler.py", line 116, in notify
    response = await handler_obj.handler(*args, **partial_data)
  File "c:\Users\Максим\Desktop\telegram bot\telegram_bot - копия.py", line 92, in process_start_command
    state = await dp.get_state()
AttributeError: 'Dispatcher' object has no attribute 'get_state'
2021-11-24 00:06:29,403 - ERROR - default_exception_handler: 1707 - Task exception was never retrieved
future: <Task finished name='Task-22' coro=<Dispatcher._process_polling_updates() done, defined at C:\Users\Максим\AppData\Roaming\Python\Python38\site-packages\aiogram\dispatcher\dispatcher.py:406> exception=AttributeError("'Dispatcher' object has no attribute 'get_state'")>
Traceback (most recent call last):
  File "C:\Users\Максим\AppData\Roaming\Python\Python38\site-packages\aiogram\dispatcher\dispatcher.py", line 414, in _process_polling_updates
    for responses in itertools.chain.from_iterable(await self.process_updates(updates, fast)):
  File "C:\Users\Максим\AppData\Roaming\Python\Python38\site-packages\aiogram\dispatcher\dispatcher.py", line 236, in process_updates
    return await asyncio.gather(*tasks)
  File "C:\Users\Максим\AppData\Roaming\Python\Python38\site-packages\aiogram\dispatcher\handler.py", line 116, in notify
    response = await handler_obj.handler(*args, **partial_data)
  File "C:\Users\Максим\AppData\Roaming\Python\Python38\site-packages\aiogram\dispatcher\dispatcher.py", line 257, in process_update
    return await self.message_handlers.notify(update.message)
  File "C:\Users\Максим\AppData\Roaming\Python\Python38\site-packages\aiogram\dispatcher\handler.py", line 116, in notify
    response = await handler_obj.handler(*args, **partial_data)
  File "c:\Users\Максим\Desktop\telegram bot\telegram_bot - копия.py", line 92, in process_start_command
    state = await dp.get_state()
AttributeError: 'Dispatcher' object has no attribute 'get_state'
2021-11-24 00:06:29,578 - ERROR - default_exception_handler: 1707 - Task exception was never retrieved
future: <Task finished name='Task-25' coro=<Dispatcher._process_polling_updates() done, defined at C:\Users\Максим\AppData\Roaming\Python\Python38\site-packages\aiogram\dispatcher\dispatcher.py:406> exception=AttributeError("'Dispatcher' object has no attribute 'get_state'")>
Traceback (most recent call last):
  File "C:\Users\Максим\AppData\Roaming\Python\Python38\site-packages\aiogram\dispatcher\dispatcher.py", line 414, in _process_polling_updates
    for responses in itertools.chain.from_iterable(await self.process_updates(updates, fast)):
  File "C:\Users\Максим\AppData\Roaming\Python\Python38\site-packages\aiogram\dispatcher\dispatcher.py", line 236, in process_updates
    return await asyncio.gather(*tasks)
  File "C:\Users\Максим\AppData\Roaming\Python\Python38\site-packages\aiogram\dispatcher\handler.py", line 116, in notify
    response = await handler_obj.handler(*args, **partial_data)
  File "C:\Users\Максим\AppData\Roaming\Python\Python38\site-packages\aiogram\dispatcher\dispatcher.py", line 257, in process_update
    return await self.message_handlers.notify(update.message)
  File "C:\Users\Максим\AppData\Roaming\Python\Python38\site-packages\aiogram\dispatcher\handler.py", line 116, in notify
    response = await handler_obj.handler(*args, **partial_data)
  File "c:\Users\Максим\Desktop\telegram bot\telegram_bot - копия.py", line 92, in process_start_command
    state = await dp.get_state()
AttributeError: 'Dispatcher' object has no attribute 'get_state'
2021-11-24 00:06:29,843 - ERROR - default_exception_handler: 1707 - Task exception was never retrieved
future: <Task finished name='Task-28' coro=<Dispatcher._process_polling_updates() done, defined at C:\Users\Максим\AppData\Roaming\Python\Python38\site-packages\aiogram\dispatcher\dispatcher.py:406> exception=AttributeError("'Dispatcher' object has no attribute 'get_state'")>
Traceback (most recent call last):
  File "C:\Users\Максим\AppData\Roaming\Python\Python38\site-packages\aiogram\dispatcher\dispatcher.py", line 414, in _process_polling_updates
    for responses in itertools.chain.from_iterable(await self.process_updates(updates, fast)):
  File "C:\Users\Максим\AppData\Roaming\Python\Python38\site-packages\aiogram\dispatcher\dispatcher.py", line 236, in process_updates
    return await asyncio.gather(*tasks)
  File "C:\Users\Максим\AppData\Roaming\Python\Python38\site-packages\aiogram\dispatcher\handler.py", line 116, in notify
    response = await handler_obj.handler(*args, **partial_data)
  File "C:\Users\Максим\AppData\Roaming\Python\Python38\site-packages\aiogram\dispatcher\dispatcher.py", line 257, in process_update
    return await self.message_handlers.notify(update.message)
  File "C:\Users\Максим\AppData\Roaming\Python\Python38\site-packages\aiogram\dispatcher\handler.py", line 116, in notify
    response = await handler_obj.handler(*args, **partial_data)
  File "c:\Users\Максим\Desktop\telegram bot\telegram_bot - копия.py", line 92, in process_start_command
    state = await dp.get_state()
AttributeError: 'Dispatcher' object has no attribute 'get_state'
2021-11-24 00:06:30,001 - ERROR - default_exception_handler: 1707 - Task exception was never retrieved
future: <Task finished name='Task-31' coro=<Dispatcher._process_polling_updates() done, defined at C:\Users\Максим\AppData\Roaming\Python\Python38\site-packages\aiogram\dispatcher\dispatcher.py:406> exception=AttributeError("'Dispatcher' object has no attribute 'get_state'")>
Traceback (most recent call last):
  File "C:\Users\Максим\AppData\Roaming\Python\Python38\site-packages\aiogram\dispatcher\dispatcher.py", line 414, in _process_polling_updates
    for responses in itertools.chain.from_iterable(await self.process_updates(updates, fast)):
  File "C:\Users\Максим\AppData\Roaming\Python\Python38\site-packages\aiogram\dispatcher\dispatcher.py", line 236, in process_updates
    return await asyncio.gather(*tasks)
  File "C:\Users\Максим\AppData\Roaming\Python\Python38\site-packages\aiogram\dispatcher\handler.py", line 116, in notify
    response = await handler_obj.handler(*args, **partial_data)
  File "C:\Users\Максим\AppData\Roaming\Python\Python38\site-packages\aiogram\dispatcher\dispatcher.py", line 257, in process_update
    return await self.message_handlers.notify(update.message)
  File "C:\Users\Максим\AppData\Roaming\Python\Python38\site-packages\aiogram\dispatcher\handler.py", line 116, in notify
    response = await handler_obj.handler(*args, **partial_data)
  File "c:\Users\Максим\Desktop\telegram bot\telegram_bot - копия.py", line 92, in process_start_command
    state = await dp.get_state()
AttributeError: 'Dispatcher' object has no attribute 'get_state'
2021-11-24 00:06:30,268 - ERROR - default_exception_handler: 1707 - Task exception was never retrieved
future: <Task finished name='Task-34' coro=<Dispatcher._process_polling_updates() done, defined at C:\Users\Максим\AppData\Roaming\Python\Python38\site-packages\aiogram\dispatcher\dispatcher.py:406> exception=AttributeError("'Dispatcher' object has no attribute 'get_state'")>
Traceback (most recent call last):
  File "C:\Users\Максим\AppData\Roaming\Python\Python38\site-packages\aiogram\dispatcher\dispatcher.py", line 414, in _process_polling_updates
    for responses in itertools.chain.from_iterable(await self.process_updates(updates, fast)):
  File "C:\Users\Максим\AppData\Roaming\Python\Python38\site-packages\aiogram\dispatcher\dispatcher.py", line 236, in process_updates
    return await asyncio.gather(*tasks)
  File "C:\Users\Максим\AppData\Roaming\Python\Python38\site-packages\aiogram\dispatcher\handler.py", line 116, in notify
    response = await handler_obj.handler(*args, **partial_data)
  File "C:\Users\Максим\AppData\Roaming\Python\Python38\site-packages\aiogram\dispatcher\dispatcher.py", line 257, in process_update
    return await self.message_handlers.notify(update.message)
  File "C:\Users\Максим\AppData\Roaming\Python\Python38\site-packages\aiogram\dispatcher\handler.py", line 116, in notify
    response = await handler_obj.handler(*args, **partial_data)
  File "c:\Users\Максим\Desktop\telegram bot\telegram_bot - копия.py", line 92, in process_start_command
    state = await dp.get_state()
AttributeError: 'Dispatcher' object has no attribute 'get_state'
2021-11-24 00:06:30,433 - ERROR - default_exception_handler: 1707 - Task exception was never retrieved
future: <Task finished name='Task-37' coro=<Dispatcher._process_polling_updates() done, defined at C:\Users\Максим\AppData\Roaming\Python\Python38\site-packages\aiogram\dispatcher\dispatcher.py:406> exception=AttributeError("'Dispatcher' object has no attribute 'get_state'")>
Traceback (most recent call last):
  File "C:\Users\Максим\AppData\Roaming\Python\Python38\site-packages\aiogram\dispatcher\dispatcher.py", line 414, in _process_polling_updates
    for responses in itertools.chain.from_iterable(await self.process_updates(updates, fast)):
  File "C:\Users\Максим\AppData\Roaming\Python\Python38\site-packages\aiogram\dispatcher\dispatcher.py", line 236, in process_updates
    return await asyncio.gather(*tasks)
  File "C:\Users\Максим\AppData\Roaming\Python\Python38\site-packages\aiogram\dispatcher\handler.py", line 116, in notify
    response = await handler_obj.handler(*args, **partial_data)
  File "C:\Users\Максим\AppData\Roaming\Python\Python38\site-packages\aiogram\dispatcher\dispatcher.py", line 257, in process_update
    return await self.message_handlers.notify(update.message)
  File "C:\Users\Максим\AppData\Roaming\Python\Python38\site-packages\aiogram\dispatcher\handler.py", line 116, in notify
    response = await handler_obj.handler(*args, **partial_data)
  File "c:\Users\Максим\Desktop\telegram bot\telegram_bot - копия.py", line 92, in process_start_command
    state = await dp.get_state()
AttributeError: 'Dispatcher' object has no attribute 'get_state'
2021-11-24 00:06:30,633 - ERROR - default_exception_handler: 1707 - Task exception was never retrieved
future: <Task finished name='Task-40' coro=<Dispatcher._process_polling_updates() done, defined at C:\Users\Максим\AppData\Roaming\Python\Python38\site-packages\aiogram\dispatcher\dispatcher.py:406> exception=AttributeError("'Dispatcher' object has no attribute 'get_state'")>
Traceback (most recent call last):
  File "C:\Users\Максим\AppData\Roaming\Python\Python38\site-packages\aiogram\dispatcher\dispatcher.py", line 414, in _process_polling_updates
    for responses in itertools.chain.from_iterable(await self.process_updates(updates, fast)):
  File "C:\Users\Максим\AppData\Roaming\Python\Python38\site-packages\aiogram\dispatcher\dispatcher.py", line 236, in process_updates
    return await asyncio.gather(*tasks)
  File "C:\Users\Максим\AppData\Roaming\Python\Python38\site-packages\aiogram\dispatcher\handler.py", line 116, in notify
    response = await handler_obj.handler(*args, **partial_data)
  File "C:\Users\Максим\AppData\Roaming\Python\Python38\site-packages\aiogram\dispatcher\dispatcher.py", line 257, in process_update
    return await self.message_handlers.notify(update.message)
  File "C:\Users\Максим\AppData\Roaming\Python\Python38\site-packages\aiogram\dispatcher\handler.py", line 116, in notify
    response = await handler_obj.handler(*args, **partial_data)
  File "c:\Users\Максим\Desktop\telegram bot\telegram_bot - копия.py", line 92, in process_start_command
    state = await dp.get_state()
AttributeError: 'Dispatcher' object has no attribute 'get_state'
2021-11-24 00:06:37,097 - ERROR - default_exception_handler: 1707 - Task exception was never retrieved
future: <Task finished name='Task-7' coro=<Dispatcher._process_polling_updates() done, defined at C:\Users\Максим\AppData\Roaming\Python\Python38\site-packages\aiogram\dispatcher\dispatcher.py:406> exception=AttributeError("'Dispatcher' object has no attribute 'get_state'")>
Traceback (most recent call last):
  File "C:\Users\Максим\AppData\Roaming\Python\Python38\site-packages\aiogram\dispatcher\dispatcher.py", line 414, in _process_polling_updates
    for responses in itertools.chain.from_iterable(await self.process_updates(updates, fast)):
  File "C:\Users\Максим\AppData\Roaming\Python\Python38\site-packages\aiogram\dispatcher\dispatcher.py", line 236, in process_updates
    return await asyncio.gather(*tasks)
  File "C:\Users\Максим\AppData\Roaming\Python\Python38\site-packages\aiogram\dispatcher\handler.py", line 116, in notify
    response = await handler_obj.handler(*args, **partial_data)
  File "C:\Users\Максим\AppData\Roaming\Python\Python38\site-packages\aiogram\dispatcher\dispatcher.py", line 257, in process_update
    return await self.message_handlers.notify(update.message)
  File "C:\Users\Максим\AppData\Roaming\Python\Python38\site-packages\aiogram\dispatcher\handler.py", line 116, in notify
    response = await handler_obj.handler(*args, **partial_data)
  File "c:\Users\Максим\Desktop\telegram bot\telegram_bot - копия.py", line 92, in process_start_command
    state = await dp.get_state()
AttributeError: 'Dispatcher' object has no attribute 'get_state'
2021-11-24 00:06:37,812 - ERROR - default_exception_handler: 1707 - Task exception was never retrieved
future: <Task finished name='Task-10' coro=<Dispatcher._process_polling_updates() done, defined at C:\Users\Максим\AppData\Roaming\Python\Python38\site-packages\aiogram\dispatcher\dispatcher.py:406> exception=AttributeError("'Dispatcher' object has no attribute 'get_state'")>
Traceback (most recent call last):
  File "C:\Users\Максим\AppData\Roaming\Python\Python38\site-packages\aiogram\dispatcher\dispatcher.py", line 414, in _process_polling_updates
    for responses in itertools.chain.from_iterable(await self.process_updates(updates, fast)):
  File "C:\Users\Максим\AppData\Roaming\Python\Python38\site-packages\aiogram\dispatcher\dispatcher.py", line 236, in process_updates
    return await asyncio.gather(*tasks)
  File "C:\Users\Максим\AppData\Roaming\Python\Python38\site-packages\aiogram\dispatcher\handler.py", line 116, in notify
    response = await handler_obj.handler(*args, **partial_data)
  File "C:\Users\Максим\AppData\Roaming\Python\Python38\site-packages\aiogram\dispatcher\dispatcher.py", line 257, in process_update
    return await self.message_handlers.notify(update.message)
  File "C:\Users\Максим\AppData\Roaming\Python\Python38\site-packages\aiogram\dispatcher\handler.py", line 116, in notify
    response = await handler_obj.handler(*args, **partial_data)
  File "c:\Users\Максим\Desktop\telegram bot\telegram_bot - копия.py", line 92, in process_start_command
    state = await dp.get_state()
AttributeError: 'Dispatcher' object has no attribute 'get_state'
2021-11-24 00:06:38,453 - ERROR - default_exception_handler: 1707 - Task exception was never retrieved
future: <Task finished name='Task-13' coro=<Dispatcher._process_polling_updates() done, defined at C:\Users\Максим\AppData\Roaming\Python\Python38\site-packages\aiogram\dispatcher\dispatcher.py:406> exception=AttributeError("'Dispatcher' object has no attribute 'get_state'")>
Traceback (most recent call last):
  File "C:\Users\Максим\AppData\Roaming\Python\Python38\site-packages\aiogram\dispatcher\dispatcher.py", line 414, in _process_polling_updates
    for responses in itertools.chain.from_iterable(await self.process_updates(updates, fast)):
  File "C:\Users\Максим\AppData\Roaming\Python\Python38\site-packages\aiogram\dispatcher\dispatcher.py", line 236, in process_updates
    return await asyncio.gather(*tasks)
  File "C:\Users\Максим\AppData\Roaming\Python\Python38\site-packages\aiogram\dispatcher\handler.py", line 116, in notify
    response = await handler_obj.handler(*args, **partial_data)
  File "C:\Users\Максим\AppData\Roaming\Python\Python38\site-packages\aiogram\dispatcher\dispatcher.py", line 257, in process_update
    return await self.message_handlers.notify(update.message)
  File "C:\Users\Максим\AppData\Roaming\Python\Python38\site-packages\aiogram\dispatcher\handler.py", line 116, in notify
    response = await handler_obj.handler(*args, **partial_data)
  File "c:\Users\Максим\Desktop\telegram bot\telegram_bot - копия.py", line 92, in process_start_command
    state = await dp.get_state()
AttributeError: 'Dispatcher' object has no attribute 'get_state'
2021-11-24 00:06:38,685 - ERROR - default_exception_handler: 1707 - Task exception was never retrieved
future: <Task finished name='Task-16' coro=<Dispatcher._process_polling_updates() done, defined at C:\Users\Максим\AppData\Roaming\Python\Python38\site-packages\aiogram\dispatcher\dispatcher.py:406> exception=AttributeError("'Dispatcher' object has no attribute 'get_state'")>
Traceback (most recent call last):
  File "C:\Users\Максим\AppData\Roaming\Python\Python38\site-packages\aiogram\dispatcher\dispatcher.py", line 414, in _process_polling_updates
    for responses in itertools.chain.from_iterable(await self.process_updates(updates, fast)):
  File "C:\Users\Максим\AppData\Roaming\Python\Python38\site-packages\aiogram\dispatcher\dispatcher.py", line 236, in process_updates
    return await asyncio.gather(*tasks)
  File "C:\Users\Максим\AppData\Roaming\Python\Python38\site-packages\aiogram\dispatcher\handler.py", line 116, in notify
    response = await handler_obj.handler(*args, **partial_data)
  File "C:\Users\Максим\AppData\Roaming\Python\Python38\site-packages\aiogram\dispatcher\dispatcher.py", line 257, in process_update
    return await self.message_handlers.notify(update.message)
  File "C:\Users\Максим\AppData\Roaming\Python\Python38\site-packages\aiogram\dispatcher\handler.py", line 116, in notify
    response = await handler_obj.handler(*args, **partial_data)
  File "c:\Users\Максим\Desktop\telegram bot\telegram_bot - копия.py", line 92, in process_start_command
    state = await dp.get_state()
AttributeError: 'Dispatcher' object has no attribute 'get_state'
2021-11-24 00:06:38,868 - ERROR - default_exception_handler: 1707 - Task exception was never retrieved
future: <Task finished name='Task-19' coro=<Dispatcher._process_polling_updates() done, defined at C:\Users\Максим\AppData\Roaming\Python\Python38\site-packages\aiogram\dispatcher\dispatcher.py:406> exception=AttributeError("'Dispatcher' object has no attribute 'get_state'")>
Traceback (most recent call last):
  File "C:\Users\Максим\AppData\Roaming\Python\Python38\site-packages\aiogram\dispatcher\dispatcher.py", line 414, in _process_polling_updates
    for responses in itertools.chain.from_iterable(await self.process_updates(updates, fast)):
  File "C:\Users\Максим\AppData\Roaming\Python\Python38\site-packages\aiogram\dispatcher\dispatcher.py", line 236, in process_updates
    return await asyncio.gather(*tasks)
  File "C:\Users\Максим\AppData\Roaming\Python\Python38\site-packages\aiogram\dispatcher\handler.py", line 116, in notify
    response = await handler_obj.handler(*args, **partial_data)
  File "C:\Users\Максим\AppData\Roaming\Python\Python38\site-packages\aiogram\dispatcher\dispatcher.py", line 257, in process_update
    return await self.message_handlers.notify(update.message)
  File "C:\Users\Максим\AppData\Roaming\Python\Python38\site-packages\aiogram\dispatcher\handler.py", line 116, in notify
    response = await handler_obj.handler(*args, **partial_data)
  File "c:\Users\Максим\Desktop\telegram bot\telegram_bot - копия.py", line 92, in process_start_command
    state = await dp.get_state()
AttributeError: 'Dispatcher' object has no attribute 'get_state'
2021-11-24 00:06:39,081 - ERROR - default_exception_handler: 1707 - Task exception was never retrieved
future: <Task finished name='Task-22' coro=<Dispatcher._process_polling_updates() done, defined at C:\Users\Максим\AppData\Roaming\Python\Python38\site-packages\aiogram\dispatcher\dispatcher.py:406> exception=AttributeError("'Dispatcher' object has no attribute 'get_state'")>
Traceback (most recent call last):
  File "C:\Users\Максим\AppData\Roaming\Python\Python38\site-packages\aiogram\dispatcher\dispatcher.py", line 414, in _process_polling_updates
    for responses in itertools.chain.from_iterable(await self.process_updates(updates, fast)):
  File "C:\Users\Максим\AppData\Roaming\Python\Python38\site-packages\aiogram\dispatcher\dispatcher.py", line 236, in process_updates
    return await asyncio.gather(*tasks)
  File "C:\Users\Максим\AppData\Roaming\Python\Python38\site-packages\aiogram\dispatcher\handler.py", line 116, in notify
    response = await handler_obj.handler(*args, **partial_data)
  File "C:\Users\Максим\AppData\Roaming\Python\Python38\site-packages\aiogram\dispatcher\dispatcher.py", line 257, in process_update
    return await self.message_handlers.notify(update.message)
  File "C:\Users\Максим\AppData\Roaming\Python\Python38\site-packages\aiogram\dispatcher\handler.py", line 116, in notify
    response = await handler_obj.handler(*args, **partial_data)
  File "c:\Users\Максим\Desktop\telegram bot\telegram_bot - копия.py", line 92, in process_start_command
    state = await dp.get_state()
AttributeError: 'Dispatcher' object has no attribute 'get_state'
2021-11-24 00:06:39,265 - ERROR - default_exception_handler: 1707 - Task exception was never retrieved
future: <Task finished name='Task-25' coro=<Dispatcher._process_polling_updates() done, defined at C:\Users\Максим\AppData\Roaming\Python\Python38\site-packages\aiogram\dispatcher\dispatcher.py:406> exception=AttributeError("'Dispatcher' object has no attribute 'get_state'")>
Traceback (most recent call last):
  File "C:\Users\Максим\AppData\Roaming\Python\Python38\site-packages\aiogram\dispatcher\dispatcher.py", line 414, in _process_polling_updates
    for responses in itertools.chain.from_iterable(await self.process_updates(updates, fast)):
  File "C:\Users\Максим\AppData\Roaming\Python\Python38\site-packages\aiogram\dispatcher\dispatcher.py", line 236, in process_updates
    return await asyncio.gather(*tasks)
  File "C:\Users\Максим\AppData\Roaming\Python\Python38\site-packages\aiogram\dispatcher\handler.py", line 116, in notify
    response = await handler_obj.handler(*args, **partial_data)
  File "C:\Users\Максим\AppData\Roaming\Python\Python38\site-packages\aiogram\dispatcher\dispatcher.py", line 257, in process_update
    return await self.message_handlers.notify(update.message)
  File "C:\Users\Максим\AppData\Roaming\Python\Python38\site-packages\aiogram\dispatcher\handler.py", line 116, in notify
    response = await handler_obj.handler(*args, **partial_data)
  File "c:\Users\Максим\Desktop\telegram bot\telegram_bot - копия.py", line 92, in process_start_command
    state = await dp.get_state()
AttributeError: 'Dispatcher' object has no attribute 'get_state'
2021-11-24 00:08:13,245 - ERROR - default_exception_handler: 1707 - Task exception was never retrieved
future: <Task finished name='Task-60' coro=<Dispatcher._process_polling_updates() done, defined at C:\Users\Максим\AppData\Roaming\Python\Python38\site-packages\aiogram\dispatcher\dispatcher.py:406> exception=AttributeError("'str' object has no attribute 'reset_state'")>
Traceback (most recent call last):
  File "C:\Users\Максим\AppData\Roaming\Python\Python38\site-packages\aiogram\dispatcher\dispatcher.py", line 414, in _process_polling_updates
    for responses in itertools.chain.from_iterable(await self.process_updates(updates, fast)):
  File "C:\Users\Максим\AppData\Roaming\Python\Python38\site-packages\aiogram\dispatcher\dispatcher.py", line 236, in process_updates
    return await asyncio.gather(*tasks)
  File "C:\Users\Максим\AppData\Roaming\Python\Python38\site-packages\aiogram\dispatcher\handler.py", line 116, in notify
    response = await handler_obj.handler(*args, **partial_data)
  File "C:\Users\Максим\AppData\Roaming\Python\Python38\site-packages\aiogram\dispatcher\dispatcher.py", line 257, in process_update
    return await self.message_handlers.notify(update.message)
  File "C:\Users\Максим\AppData\Roaming\Python\Python38\site-packages\aiogram\dispatcher\handler.py", line 116, in notify
    response = await handler_obj.handler(*args, **partial_data)
  File "c:\Users\Максим\Desktop\telegram bot\telegram_bot - копия.py", line 141, in process_start_command
    await state.reset_state()
AttributeError: 'str' object has no attribute 'reset_state'
2021-11-24 00:11:41,653 - ERROR - default_exception_handler: 1707 - Task exception was never retrieved
future: <Task finished name='Task-47' coro=<Dispatcher._process_polling_updates() done, defined at C:\Users\Максим\AppData\Roaming\Python\Python38\site-packages\aiogram\dispatcher\dispatcher.py:406> exception=AttributeError("'NoneType' object has no attribute 'set_state'")>
Traceback (most recent call last):
  File "C:\Users\Максим\AppData\Roaming\Python\Python38\site-packages\aiogram\dispatcher\dispatcher.py", line 414, in _process_polling_updates
    for responses in itertools.chain.from_iterable(await self.process_updates(updates, fast)):
  File "C:\Users\Максим\AppData\Roaming\Python\Python38\site-packages\aiogram\dispatcher\dispatcher.py", line 236, in process_updates
    return await asyncio.gather(*tasks)
  File "C:\Users\Максим\AppData\Roaming\Python\Python38\site-packages\aiogram\dispatcher\handler.py", line 116, in notify
    response = await handler_obj.handler(*args, **partial_data)
  File "C:\Users\Максим\AppData\Roaming\Python\Python38\site-packages\aiogram\dispatcher\dispatcher.py", line 257, in process_update
    return await self.message_handlers.notify(update.message)
  File "C:\Users\Максим\AppData\Roaming\Python\Python38\site-packages\aiogram\dispatcher\handler.py", line 116, in notify
    response = await handler_obj.handler(*args, **partial_data)
  File "c:\Users\Максим\Desktop\telegram bot\telegram_bot - копия.py", line 136, in process_start_command
    await state.set_state(TestStates.all()[1])
AttributeError: 'NoneType' object has no attribute 'set_state'
2021-11-24 00:11:43,311 - ERROR - default_exception_handler: 1707 - Task exception was never retrieved
future: <Task finished name='Task-50' coro=<Dispatcher._process_polling_updates() done, defined at C:\Users\Максим\AppData\Roaming\Python\Python38\site-packages\aiogram\dispatcher\dispatcher.py:406> exception=AttributeError("'NoneType' object has no attribute 'set_state'")>
Traceback (most recent call last):
  File "C:\Users\Максим\AppData\Roaming\Python\Python38\site-packages\aiogram\dispatcher\dispatcher.py", line 414, in _process_polling_updates
    for responses in itertools.chain.from_iterable(await self.process_updates(updates, fast)):
  File "C:\Users\Максим\AppData\Roaming\Python\Python38\site-packages\aiogram\dispatcher\dispatcher.py", line 236, in process_updates
    return await asyncio.gather(*tasks)
  File "C:\Users\Максим\AppData\Roaming\Python\Python38\site-packages\aiogram\dispatcher\handler.py", line 116, in notify
    response = await handler_obj.handler(*args, **partial_data)
  File "C:\Users\Максим\AppData\Roaming\Python\Python38\site-packages\aiogram\dispatcher\dispatcher.py", line 257, in process_update
    return await self.message_handlers.notify(update.message)
  File "C:\Users\Максим\AppData\Roaming\Python\Python38\site-packages\aiogram\dispatcher\handler.py", line 116, in notify
    response = await handler_obj.handler(*args, **partial_data)
  File "c:\Users\Максим\Desktop\telegram bot\telegram_bot - копия.py", line 136, in process_start_command
    await state.set_state(TestStates.all()[1])
AttributeError: 'NoneType' object has no attribute 'set_state'
2021-11-24 00:11:44,264 - ERROR - default_exception_handler: 1707 - Task exception was never retrieved
future: <Task finished name='Task-53' coro=<Dispatcher._process_polling_updates() done, defined at C:\Users\Максим\AppData\Roaming\Python\Python38\site-packages\aiogram\dispatcher\dispatcher.py:406> exception=AttributeError("'NoneType' object has no attribute 'set_state'")>
Traceback (most recent call last):
  File "C:\Users\Максим\AppData\Roaming\Python\Python38\site-packages\aiogram\dispatcher\dispatcher.py", line 414, in _process_polling_updates
    for responses in itertools.chain.from_iterable(await self.process_updates(updates, fast)):
  File "C:\Users\Максим\AppData\Roaming\Python\Python38\site-packages\aiogram\dispatcher\dispatcher.py", line 236, in process_updates
    return await asyncio.gather(*tasks)
  File "C:\Users\Максим\AppData\Roaming\Python\Python38\site-packages\aiogram\dispatcher\handler.py", line 116, in notify
    response = await handler_obj.handler(*args, **partial_data)
  File "C:\Users\Максим\AppData\Roaming\Python\Python38\site-packages\aiogram\dispatcher\dispatcher.py", line 257, in process_update
    return await self.message_handlers.notify(update.message)
  File "C:\Users\Максим\AppData\Roaming\Python\Python38\site-packages\aiogram\dispatcher\handler.py", line 116, in notify
    response = await handler_obj.handler(*args, **partial_data)
  File "c:\Users\Максим\Desktop\telegram bot\telegram_bot - копия.py", line 136, in process_start_command
    await state.set_state(TestStates.all()[1])
AttributeError: 'NoneType' object has no attribute 'set_state'
2021-11-24 00:11:44,960 - ERROR - default_exception_handler: 1707 - Task exception was never retrieved
future: <Task finished name='Task-56' coro=<Dispatcher._process_polling_updates() done, defined at C:\Users\Максим\AppData\Roaming\Python\Python38\site-packages\aiogram\dispatcher\dispatcher.py:406> exception=AttributeError("'NoneType' object has no attribute 'set_state'")>
Traceback (most recent call last):
  File "C:\Users\Максим\AppData\Roaming\Python\Python38\site-packages\aiogram\dispatcher\dispatcher.py", line 414, in _process_polling_updates
    for responses in itertools.chain.from_iterable(await self.process_updates(updates, fast)):
  File "C:\Users\Максим\AppData\Roaming\Python\Python38\site-packages\aiogram\dispatcher\dispatcher.py", line 236, in process_updates
    return await asyncio.gather(*tasks)
  File "C:\Users\Максим\AppData\Roaming\Python\Python38\site-packages\aiogram\dispatcher\handler.py", line 116, in notify
    response = await handler_obj.handler(*args, **partial_data)
  File "C:\Users\Максим\AppData\Roaming\Python\Python38\site-packages\aiogram\dispatcher\dispatcher.py", line 257, in process_update
    return await self.message_handlers.notify(update.message)
  File "C:\Users\Максим\AppData\Roaming\Python\Python38\site-packages\aiogram\dispatcher\handler.py", line 116, in notify
    response = await handler_obj.handler(*args, **partial_data)
  File "c:\Users\Максим\Desktop\telegram bot\telegram_bot - копия.py", line 136, in process_start_command
    await state.set_state(TestStates.all()[1])
AttributeError: 'NoneType' object has no attribute 'set_state'
2021-11-24 00:11:45,397 - ERROR - default_exception_handler: 1707 - Task exception was never retrieved
future: <Task finished name='Task-59' coro=<Dispatcher._process_polling_updates() done, defined at C:\Users\Максим\AppData\Roaming\Python\Python38\site-packages\aiogram\dispatcher\dispatcher.py:406> exception=AttributeError("'NoneType' object has no attribute 'set_state'")>
Traceback (most recent call last):
  File "C:\Users\Максим\AppData\Roaming\Python\Python38\site-packages\aiogram\dispatcher\dispatcher.py", line 414, in _process_polling_updates
    for responses in itertools.chain.from_iterable(await self.process_updates(updates, fast)):
  File "C:\Users\Максим\AppData\Roaming\Python\Python38\site-packages\aiogram\dispatcher\dispatcher.py", line 236, in process_updates
    return await asyncio.gather(*tasks)
  File "C:\Users\Максим\AppData\Roaming\Python\Python38\site-packages\aiogram\dispatcher\handler.py", line 116, in notify
    response = await handler_obj.handler(*args, **partial_data)
  File "C:\Users\Максим\AppData\Roaming\Python\Python38\site-packages\aiogram\dispatcher\dispatcher.py", line 257, in process_update
    return await self.message_handlers.notify(update.message)
  File "C:\Users\Максим\AppData\Roaming\Python\Python38\site-packages\aiogram\dispatcher\handler.py", line 116, in notify
    response = await handler_obj.handler(*args, **partial_data)
  File "c:\Users\Максим\Desktop\telegram bot\telegram_bot - копия.py", line 136, in process_start_command
    await state.set_state(TestStates.all()[1])
AttributeError: 'NoneType' object has no attribute 'set_state'
2021-11-24 00:11:45,669 - ERROR - default_exception_handler: 1707 - Task exception was never retrieved
future: <Task finished name='Task-62' coro=<Dispatcher._process_polling_updates() done, defined at C:\Users\Максим\AppData\Roaming\Python\Python38\site-packages\aiogram\dispatcher\dispatcher.py:406> exception=AttributeError("'NoneType' object has no attribute 'set_state'")>
Traceback (most recent call last):
  File "C:\Users\Максим\AppData\Roaming\Python\Python38\site-packages\aiogram\dispatcher\dispatcher.py", line 414, in _process_polling_updates
    for responses in itertools.chain.from_iterable(await self.process_updates(updates, fast)):
  File "C:\Users\Максим\AppData\Roaming\Python\Python38\site-packages\aiogram\dispatcher\dispatcher.py", line 236, in process_updates
    return await asyncio.gather(*tasks)
  File "C:\Users\Максим\AppData\Roaming\Python\Python38\site-packages\aiogram\dispatcher\handler.py", line 116, in notify
    response = await handler_obj.handler(*args, **partial_data)
  File "C:\Users\Максим\AppData\Roaming\Python\Python38\site-packages\aiogram\dispatcher\dispatcher.py", line 257, in process_update
    return await self.message_handlers.notify(update.message)
  File "C:\Users\Максим\AppData\Roaming\Python\Python38\site-packages\aiogram\dispatcher\handler.py", line 116, in notify
    response = await handler_obj.handler(*args, **partial_data)
  File "c:\Users\Максим\Desktop\telegram bot\telegram_bot - копия.py", line 136, in process_start_command
    await state.set_state(TestStates.all()[1])
AttributeError: 'NoneType' object has no attribute 'set_state'
2021-11-24 00:11:45,844 - ERROR - default_exception_handler: 1707 - Task exception was never retrieved
future: <Task finished name='Task-65' coro=<Dispatcher._process_polling_updates() done, defined at C:\Users\Максим\AppData\Roaming\Python\Python38\site-packages\aiogram\dispatcher\dispatcher.py:406> exception=AttributeError("'NoneType' object has no attribute 'set_state'")>
Traceback (most recent call last):
  File "C:\Users\Максим\AppData\Roaming\Python\Python38\site-packages\aiogram\dispatcher\dispatcher.py", line 414, in _process_polling_updates
    for responses in itertools.chain.from_iterable(await self.process_updates(updates, fast)):
  File "C:\Users\Максим\AppData\Roaming\Python\Python38\site-packages\aiogram\dispatcher\dispatcher.py", line 236, in process_updates
    return await asyncio.gather(*tasks)
  File "C:\Users\Максим\AppData\Roaming\Python\Python38\site-packages\aiogram\dispatcher\handler.py", line 116, in notify
    response = await handler_obj.handler(*args, **partial_data)
  File "C:\Users\Максим\AppData\Roaming\Python\Python38\site-packages\aiogram\dispatcher\dispatcher.py", line 257, in process_update
    return await self.message_handlers.notify(update.message)
  File "C:\Users\Максим\AppData\Roaming\Python\Python38\site-packages\aiogram\dispatcher\handler.py", line 116, in notify
    response = await handler_obj.handler(*args, **partial_data)
  File "c:\Users\Максим\Desktop\telegram bot\telegram_bot - копия.py", line 136, in process_start_command
    await state.set_state(TestStates.all()[1])
AttributeError: 'NoneType' object has no attribute 'set_state'
2021-11-24 00:11:46,015 - ERROR - default_exception_handler: 1707 - Task exception was never retrieved
future: <Task finished name='Task-68' coro=<Dispatcher._process_polling_updates() done, defined at C:\Users\Максим\AppData\Roaming\Python\Python38\site-packages\aiogram\dispatcher\dispatcher.py:406> exception=AttributeError("'NoneType' object has no attribute 'set_state'")>
Traceback (most recent call last):
  File "C:\Users\Максим\AppData\Roaming\Python\Python38\site-packages\aiogram\dispatcher\dispatcher.py", line 414, in _process_polling_updates
    for responses in itertools.chain.from_iterable(await self.process_updates(updates, fast)):
  File "C:\Users\Максим\AppData\Roaming\Python\Python38\site-packages\aiogram\dispatcher\dispatcher.py", line 236, in process_updates
    return await asyncio.gather(*tasks)
  File "C:\Users\Максим\AppData\Roaming\Python\Python38\site-packages\aiogram\dispatcher\handler.py", line 116, in notify
    response = await handler_obj.handler(*args, **partial_data)
  File "C:\Users\Максим\AppData\Roaming\Python\Python38\site-packages\aiogram\dispatcher\dispatcher.py", line 257, in process_update
    return await self.message_handlers.notify(update.message)
  File "C:\Users\Максим\AppData\Roaming\Python\Python38\site-packages\aiogram\dispatcher\handler.py", line 116, in notify
    response = await handler_obj.handler(*args, **partial_data)
  File "c:\Users\Максим\Desktop\telegram bot\telegram_bot - копия.py", line 136, in process_start_command
    await state.set_state(TestStates.all()[1])
AttributeError: 'NoneType' object has no attribute 'set_state'
2021-11-24 00:11:46,212 - ERROR - default_exception_handler: 1707 - Task exception was never retrieved
future: <Task finished name='Task-71' coro=<Dispatcher._process_polling_updates() done, defined at C:\Users\Максим\AppData\Roaming\Python\Python38\site-packages\aiogram\dispatcher\dispatcher.py:406> exception=AttributeError("'NoneType' object has no attribute 'set_state'")>
Traceback (most recent call last):
  File "C:\Users\Максим\AppData\Roaming\Python\Python38\site-packages\aiogram\dispatcher\dispatcher.py", line 414, in _process_polling_updates
    for responses in itertools.chain.from_iterable(await self.process_updates(updates, fast)):
  File "C:\Users\Максим\AppData\Roaming\Python\Python38\site-packages\aiogram\dispatcher\dispatcher.py", line 236, in process_updates
    return await asyncio.gather(*tasks)
  File "C:\Users\Максим\AppData\Roaming\Python\Python38\site-packages\aiogram\dispatcher\handler.py", line 116, in notify
    response = await handler_obj.handler(*args, **partial_data)
  File "C:\Users\Максим\AppData\Roaming\Python\Python38\site-packages\aiogram\dispatcher\dispatcher.py", line 257, in process_update
    return await self.message_handlers.notify(update.message)
  File "C:\Users\Максим\AppData\Roaming\Python\Python38\site-packages\aiogram\dispatcher\handler.py", line 116, in notify
    response = await handler_obj.handler(*args, **partial_data)
  File "c:\Users\Максим\Desktop\telegram bot\telegram_bot - копия.py", line 136, in process_start_command
    await state.set_state(TestStates.all()[1])
AttributeError: 'NoneType' object has no attribute 'set_state'
2021-11-24 00:11:46,377 - ERROR - default_exception_handler: 1707 - Task exception was never retrieved
future: <Task finished name='Task-74' coro=<Dispatcher._process_polling_updates() done, defined at C:\Users\Максим\AppData\Roaming\Python\Python38\site-packages\aiogram\dispatcher\dispatcher.py:406> exception=AttributeError("'NoneType' object has no attribute 'set_state'")>
Traceback (most recent call last):
  File "C:\Users\Максим\AppData\Roaming\Python\Python38\site-packages\aiogram\dispatcher\dispatcher.py", line 414, in _process_polling_updates
    for responses in itertools.chain.from_iterable(await self.process_updates(updates, fast)):
  File "C:\Users\Максим\AppData\Roaming\Python\Python38\site-packages\aiogram\dispatcher\dispatcher.py", line 236, in process_updates
    return await asyncio.gather(*tasks)
  File "C:\Users\Максим\AppData\Roaming\Python\Python38\site-packages\aiogram\dispatcher\handler.py", line 116, in notify
    response = await handler_obj.handler(*args, **partial_data)
  File "C:\Users\Максим\AppData\Roaming\Python\Python38\site-packages\aiogram\dispatcher\dispatcher.py", line 257, in process_update
    return await self.message_handlers.notify(update.message)
  File "C:\Users\Максим\AppData\Roaming\Python\Python38\site-packages\aiogram\dispatcher\handler.py", line 116, in notify
    response = await handler_obj.handler(*args, **partial_data)
  File "c:\Users\Максим\Desktop\telegram bot\telegram_bot - копия.py", line 136, in process_start_command
    await state.set_state(TestStates.all()[1])
AttributeError: 'NoneType' object has no attribute 'set_state'
2021-11-24 00:12:54,142 - ERROR - default_exception_handler: 1707 - Task exception was never retrieved
future: <Task finished name='Task-113' coro=<Dispatcher._process_polling_updates() done, defined at C:\Users\Максим\AppData\Roaming\Python\Python38\site-packages\aiogram\dispatcher\dispatcher.py:406> exception=AttributeError("'NoneType' object has no attribute 'set_state'")>
Traceback (most recent call last):
  File "C:\Users\Максим\AppData\Roaming\Python\Python38\site-packages\aiogram\dispatcher\dispatcher.py", line 414, in _process_polling_updates
    for responses in itertools.chain.from_iterable(await self.process_updates(updates, fast)):
  File "C:\Users\Максим\AppData\Roaming\Python\Python38\site-packages\aiogram\dispatcher\dispatcher.py", line 236, in process_updates
    return await asyncio.gather(*tasks)
  File "C:\Users\Максим\AppData\Roaming\Python\Python38\site-packages\aiogram\dispatcher\handler.py", line 116, in notify
    response = await handler_obj.handler(*args, **partial_data)
  File "C:\Users\Максим\AppData\Roaming\Python\Python38\site-packages\aiogram\dispatcher\dispatcher.py", line 257, in process_update
    return await self.message_handlers.notify(update.message)
  File "C:\Users\Максим\AppData\Roaming\Python\Python38\site-packages\aiogram\dispatcher\handler.py", line 116, in notify
    response = await handler_obj.handler(*args, **partial_data)
  File "c:\Users\Максим\Desktop\telegram bot\telegram_bot - копия.py", line 136, in process_start_command
    await state.set_state(TestStates.all()[1])
AttributeError: 'NoneType' object has no attribute 'set_state'
